2025-06-09 12:17:37,232 - ai_assistant.cli.commands - ERROR - Error during review process: 'GitHubService' object has no attribute 'get_repository_context'
Traceback (most recent call last):
  File "/Users/vidit/Documents/Dev/ass/src/ai_assistant/cli/commands.py", line 66, in review_changes
    repo_context = await self.github_service.get_repository_context()
                         ^^^^^^^^^^^^^^^^^^^^^^^^^^^^^^^^^^^^^^^^^^
AttributeError: 'GitHubService' object has no attribute 'get_repository_context'
2025-06-09 12:18:27,968 - ai_assistant.cli.commands - ERROR - Error during review process: GitHubService.get_repository_context() missing 1 required positional argument: 'repo_path'
Traceback (most recent call last):
  File "/Users/vidit/Documents/Dev/ass/src/ai_assistant/cli/commands.py", line 66, in review_changes
    repo_context = await self.github_service.get_repository_context()
                         ^^^^^^^^^^^^^^^^^^^^^^^^^^^^^^^^^^^^^^^^^^^^
TypeError: GitHubService.get_repository_context() missing 1 required positional argument: 'repo_path'
2025-06-09 12:19:34,311 - ai_assistant.cli.commands - ERROR - Error during review process: Not a Git repository. Cannot review changes.
Traceback (most recent call last):
  File "/Users/vidit/Documents/Dev/ass/src/ai_assistant/cli/commands.py", line 68, in review_changes
    raise AIAssistantError("Not a Git repository. Cannot review changes.")
ai_assistant.core.exceptions.AIAssistantError: Not a Git repository. Cannot review changes.
2025-06-09 12:21:48,884 - ai_assistant.cli.commands - ERROR - Error during review process: Not a Git repository. Cannot review changes.
Traceback (most recent call last):
  File "/Users/vidit/Documents/Dev/ass/src/ai_assistant/cli/commands.py", line 68, in review_changes
    raise AIAssistantError("Not a Git repository. Cannot review changes.")
ai_assistant.core.exceptions.AIAssistantError: Not a Git repository. Cannot review changes.
2025-06-09 13:16:58,212 - ai_assistant.cli.commands - ERROR - Error during code generation: Session not initialized
Traceback (most recent call last):
  File "/Users/vidit/Documents/Dev/ass/src/ai_assistant/cli/commands.py", line 57, in generate_code
    async for chunk in ai_service.stream_generate(request):
  File "/Users/vidit/Documents/Dev/ass/src/ai_assistant/services/ai_service.py", line 156, in stream_generate
    async for chunk in self._stream_ollama(request):
  File "/Users/vidit/Documents/Dev/ass/src/ai_assistant/services/ai_service.py", line 165, in _stream_ollama
    raise AIServiceError("Session not initialized")
ai_assistant.core.exceptions.AIServiceError: Session not initialized
2025-06-09 16:58:23,021 - ai_assistant.services.file_service - INFO - Successfully wrote changes to file: test
2025-06-09 17:50:00,219 - ai_assistant.cli.commands - ERROR - Error during review process: Not a Git repository. Cannot review changes.
Traceback (most recent call last):
  File "/Users/vidit/Documents/Dev/ass/src/ai_assistant/cli/commands.py", line 77, in review_changes
    raise AIAssistantError("Not a Git repository. Cannot review changes.")
ai_assistant.core.exceptions.AIAssistantError: Not a Git repository. Cannot review changes.
2025-06-09 17:51:20,448 - ai_assistant.cli.commands - ERROR - Error during review process: Not a Git repository. Cannot review changes.
Traceback (most recent call last):
  File "/Users/vidit/Documents/Dev/ass/src/ai_assistant/cli/commands.py", line 77, in review_changes
    raise AIAssistantError("Not a Git repository. Cannot review changes.")
ai_assistant.core.exceptions.AIAssistantError: Not a Git repository. Cannot review changes.
2025-06-09 17:52:04,007 - ai_assistant.cli.commands - ERROR - Error during review process: Not a Git repository. Cannot review changes.
Traceback (most recent call last):
  File "/Users/vidit/Documents/Dev/ass/src/ai_assistant/cli/commands.py", line 77, in review_changes
    raise AIAssistantError("Not a Git repository. Cannot review changes.")
ai_assistant.core.exceptions.AIAssistantError: Not a Git repository. Cannot review changes.
2025-06-09 17:52:58,368 - ai_assistant.cli.commands - ERROR - Error during review process: Not a Git repository. Cannot review changes.
Traceback (most recent call last):
  File "/Users/vidit/Documents/Dev/ass/src/ai_assistant/cli/commands.py", line 77, in review_changes
    raise AIAssistantError("Not a Git repository. Cannot review changes.")
ai_assistant.core.exceptions.AIAssistantError: Not a Git repository. Cannot review changes.
2025-06-09 17:53:01,683 - ai_assistant.cli.commands - ERROR - Error during review process: Not a Git repository. Cannot review changes.
Traceback (most recent call last):
  File "/Users/vidit/Documents/Dev/ass/src/ai_assistant/cli/commands.py", line 77, in review_changes
    raise AIAssistantError("Not a Git repository. Cannot review changes.")
ai_assistant.core.exceptions.AIAssistantError: Not a Git repository. Cannot review changes.
2025-06-09 17:53:50,306 - ai_assistant.cli.commands - ERROR - Error during review process: Not a Git repository. Cannot review changes.
Traceback (most recent call last):
  File "/Users/vidit/Documents/Dev/ass/src/ai_assistant/cli/commands.py", line 77, in review_changes
    raise AIAssistantError("Not a Git repository. Cannot review changes.")
ai_assistant.core.exceptions.AIAssistantError: Not a Git repository. Cannot review changes.
2025-06-09 18:36:23,976 - ai_assistant.cli.commands - ERROR - Error during review process: 'GitHubService' object has no attribute 'git_utils'
Traceback (most recent call last):
  File "/Users/vidit/Documents/Dev/ass/src/ai_assistant/cli/commands.py", line 84, in review_changes
    await self.github_service.git_utils.add_all(repo_path)
          ^^^^^^^^^^^^^^^^^^^^^^^^^^^^^
AttributeError: 'GitHubService' object has no attribute 'git_utils'. Did you mean: 'file_utils'?
2025-06-09 18:37:29,088 - ai_assistant.cli.commands - ERROR - Error during review process: object async_generator can't be used in 'await' expression
Traceback (most recent call last):
  File "/Users/vidit/Documents/Dev/ass/src/ai_assistant/cli/commands.py", line 101, in review_changes
    commit_message = await self._generate_commit_message(staged_diff)
                     ^^^^^^^^^^^^^^^^^^^^^^^^^^^^^^^^^^^^^^^^^^^^^^^^
  File "/Users/vidit/Documents/Dev/ass/src/ai_assistant/cli/commands.py", line 270, in _generate_commit_message
    commit_message = await ai_service.stream_generate(request)
                     ^^^^^^^^^^^^^^^^^^^^^^^^^^^^^^^^^^^^^^^^^
TypeError: object async_generator can't be used in 'await' expression
2025-06-09 18:44:58,348 - ai_assistant.cli.commands - ERROR - Error during review process: cannot access local variable 'GitUtils' where it is not associated with a value
Traceback (most recent call last):
  File "/Users/vidit/Documents/Dev/ass/src/ai_assistant/cli/commands.py", line 85, in review_changes
    git_utils = GitUtils()
                ^^^^^^^^
UnboundLocalError: cannot access local variable 'GitUtils' where it is not associated with a value
2025-06-09 19:28:58,342 - ai_assistant.cli.commands - ERROR - Error during review process: 
Traceback (most recent call last):
  File "/Users/vidit/Documents/Dev/ass/src/ai_assistant/cli/commands.py", line 84, in review_changes
    if click.confirm("Would you like to stage all changes (including untracked files)?", default=True):
       ^^^^^^^^^^^^^^^^^^^^^^^^^^^^^^^^^^^^^^^^^^^^^^^^^^^^^^^^^^^^^^^^^^^^^^^^^^^^^^^^^^^^^^^^^^^^^^^
  File "/Library/Frameworks/Python.framework/Versions/3.12/lib/python3.12/site-packages/click/termui.py", line 235, in confirm
    raise Abort() from None
click.exceptions.Abort
2025-06-09 20:34:41,715 - ai_assistant.services.file_service - ERROR - Unexpected error reading file ..: [Errno 21] Is a directory: '..'
2025-06-10 18:23:04,748 - ai_assistant.cli.commands - ERROR - Error during review process: Error getting staged diff: git: 'copy' is not a git command. See 'git --help'.

The most similar commands are
	apply
	clone
Traceback (most recent call last):
  File "/Users/vidit/Documents/Dev/ass copy/src/ai_assistant/cli/commands.py", line 73, in review_changes
    staged_diff = await self.git_utils.get_staged_diff(repo_path)
                  ^^^^^^^^^^^^^^^^^^^^^^^^^^^^^^^^^^^^^^^^^^^^^^^
  File "/Users/vidit/Documents/Dev/ass copy/src/ai_assistant/utils/git_utils.py", line 21, in get_staged_diff
    raise Exception(f"Error getting staged diff: {stderr.decode().strip()}")
Exception: Error getting staged diff: git: 'copy' is not a git command. See 'git --help'.

The most similar commands are
	apply
	clone
2025-06-10 18:23:43,713 - ai_assistant.cli.commands - ERROR - Error during review process: Error getting staged diff: git: 'copy' is not a git command. See 'git --help'.

The most similar commands are
	apply
	clone
Traceback (most recent call last):
  File "/Users/vidit/Documents/Dev/ass copy/src/ai_assistant/cli/commands.py", line 73, in review_changes
    staged_diff = await self.git_utils.get_staged_diff(repo_path)
                  ^^^^^^^^^^^^^^^^^^^^^^^^^^^^^^^^^^^^^^^^^^^^^^^
  File "/Users/vidit/Documents/Dev/ass copy/src/ai_assistant/utils/git_utils.py", line 21, in get_staged_diff
    raise Exception(f"Error getting staged diff: {stderr.decode().strip()}")
Exception: Error getting staged diff: git: 'copy' is not a git command. See 'git --help'.

The most similar commands are
	apply
	clone
2025-06-10 18:28:25,376 - ai_assistant.cli.commands - ERROR - Error during review process: Error getting staged diff: git: 'copy' is not a git command. See 'git --help'.

The most similar commands are
	apply
	clone
Traceback (most recent call last):
  File "/Users/vidit/Documents/Dev/ass copy/src/ai_assistant/cli/commands.py", line 73, in review_changes
    staged_diff = await self.git_utils.get_staged_diff(repo_path)
                  ^^^^^^^^^^^^^^^^^^^^^^^^^^^^^^^^^^^^^^^^^^^^^^^
  File "/Users/vidit/Documents/Dev/ass copy/src/ai_assistant/utils/git_utils.py", line 21, in get_staged_diff
    raise Exception(f"Error getting staged diff: {stderr.decode().strip()}")
Exception: Error getting staged diff: git: 'copy' is not a git command. See 'git --help'.

The most similar commands are
	apply
	clone
2025-06-10 18:29:56,457 - ai_assistant.cli.commands - ERROR - Error during review process: Error staging changes: git: 'copy' is not a git command. See 'git --help'.

The most similar commands are
	apply
	clone
Traceback (most recent call last):
  File "/Users/vidit/Documents/Dev/ass copy/src/ai_assistant/cli/commands.py", line 77, in review_changes
    await self.git_utils.add_all(repo_path)
  File "/Users/vidit/Documents/Dev/ass copy/src/ai_assistant/utils/git_utils.py", line 150, in add_all
    raise Exception(f"Error staging changes: {stderr.decode().strip()}")
Exception: Error staging changes: git: 'copy' is not a git command. See 'git --help'.

The most similar commands are
	apply
	clone
2025-06-10 18:31:26,506 - ai_assistant.cli.commands - ERROR - Error during review process: Error getting staged diff: git: 'copy' is not a git command. See 'git --help'.

The most similar commands are
	apply
	clone
Traceback (most recent call last):
  File "/Users/vidit/Documents/Dev/ass copy/src/ai_assistant/cli/commands.py", line 73, in review_changes
    staged_diff = await self.git_utils.get_staged_diff(repo_path)
                  ^^^^^^^^^^^^^^^^^^^^^^^^^^^^^^^^^^^^^^^^^^^^^^^
  File "/Users/vidit/Documents/Dev/ass copy/src/ai_assistant/utils/git_utils.py", line 21, in get_staged_diff
    raise Exception(f"Error getting staged diff: {stderr.decode().strip()}")
Exception: Error getting staged diff: git: 'copy' is not a git command. See 'git --help'.

The most similar commands are
	apply
	clone
2025-06-10 18:32:28,895 - ai_assistant.cli.commands - ERROR - Error during review process: Error getting staged diff: git: 'copy' is not a git command. See 'git --help'.

The most similar commands are
	apply
	clone
Traceback (most recent call last):
  File "/Users/vidit/Documents/Dev/ass copy/src/ai_assistant/cli/commands.py", line 73, in review_changes
    staged_diff = await self.git_utils.get_staged_diff(repo_path)
                  ^^^^^^^^^^^^^^^^^^^^^^^^^^^^^^^^^^^^^^^^^^^^^^^
  File "/Users/vidit/Documents/Dev/ass copy/src/ai_assistant/utils/git_utils.py", line 21, in get_staged_diff
    raise Exception(f"Error getting staged diff: {stderr.decode().strip()}")
Exception: Error getting staged diff: git: 'copy' is not a git command. See 'git --help'.

The most similar commands are
	apply
	clone
2025-06-10 18:33:53,697 - ai_assistant.cli.commands - ERROR - Error during review process: Error getting staged diff: git: 'copy' is not a git command. See 'git --help'.

The most similar commands are
	apply
	clone
Traceback (most recent call last):
  File "/Users/vidit/Documents/Dev/ass copy/src/ai_assistant/cli/commands.py", line 73, in review_changes
    staged_diff = await self.git_utils.get_staged_diff(repo_path)
                  ^^^^^^^^^^^^^^^^^^^^^^^^^^^^^^^^^^^^^^^^^^^^^^^
  File "/Users/vidit/Documents/Dev/ass copy/src/ai_assistant/utils/git_utils.py", line 21, in get_staged_diff
    raise Exception(f"Error getting staged diff: {stderr.decode().strip()}")
Exception: Error getting staged diff: git: 'copy' is not a git command. See 'git --help'.

The most similar commands are
	apply
	clone
2025-06-10 18:36:55,381 - ai_assistant.cli.commands - ERROR - Error during review process: Error getting staged diff: git: 'copy' is not a git command. See 'git --help'.

The most similar commands are
	apply
	clone
Traceback (most recent call last):
  File "/Users/vidit/Documents/Dev/ass copy/src/ai_assistant/cli/commands.py", line 73, in review_changes
    staged_diff = await self.git_utils.get_staged_diff(repo_path)
                  ^^^^^^^^^^^^^^^^^^^^^^^^^^^^^^^^^^^^^^^^^^^^^^^
  File "/Users/vidit/Documents/Dev/ass copy/src/ai_assistant/utils/git_utils.py", line 21, in get_staged_diff
    raise Exception(f"Error getting staged diff: {stderr.decode().strip()}")
Exception: Error getting staged diff: git: 'copy' is not a git command. See 'git --help'.

The most similar commands are
	apply
	clone
2025-06-10 19:59:42,036 - ai_assistant.services.file_service - INFO - Successfully wrote changes to file: README.md
2025-06-10 19:59:59,376 - ai_assistant.services.file_service - INFO - Successfully wrote changes to file: README.md
2025-06-10 20:29:58,317 - ai_assistant.services.file_service - INFO - Successfully wrote changes to file: config.py
2025-06-10 20:37:11,354 - ai_assistant.services.file_service - INFO - Successfully wrote changes to file: execptions.py
